<?xml version="1.0" encoding="utf-8"?>
<robot xmlns:xacro="http://www.ros.org/wiki/xacro" name="quadruped_robot">
    <xacro:macro name="quadruped_robot" params="quadruped_id:='quadruped_robot' description_pkg:='' connected_to:='' xyz:='0 0 0' rpy:='0 0 0' safety_distance:=0">
        <xacro:unless value="${not connected_to}">
            <joint name="${connected_to}_joint" type="fixed">
                <parent link="${connected_to}"/>
                <child link="qr_link0"/>
                <origin rpy="{rpy}" xyz="${xyz}"/>
            </joint>
        </xacro:unless>

        <link
            name="qr_link0">
            <inertial>
            <origin
                xyz="0 0 -0.007924"
                rpy="0 0 0" />
            <mass
                value="0.11328" />
            <inertia
                ixx="0"
                ixy="0"
                ixz="0"
                iyy="0"
                iyz="0"
                izz="0" />
            </inertial>
            <visual>
            <origin
                xyz="0 0 0"
                rpy="0 0 0" />
            <geometry>
                <mesh
                filename="package://quadruped_robot/meshes/qr_link0.STL" />
            </geometry>
            <material
                name="">
                <color
                rgba="0 0 1 1" />
            </material>
            </visual>
            <collision>
            <origin
                xyz="0 0 0"
                rpy="0 0 0" />
            <geometry>
                <mesh
                filename="package://quadruped_robot/meshes/qr_link0.STL" />
            </geometry>
            </collision>
        </link>
        <link
            name="qr_fl_link1">
            <inertial>
            <origin
                xyz="0.014583 6.439E-05 -0.00032113"
                rpy="0 0 0" />
            <mass
                value="0.011527" />
            <inertia
                ixx="0"
                ixy="0"
                ixz="0"
                iyy="0"
                iyz="0"
                izz="0" />
            </inertial>
            <visual>
            <origin
                xyz="0 0 0"
                rpy="0 0 0" />
            <geometry>
                <mesh
                filename="package://quadruped_robot/meshes/qr_fl_link1.STL" />
            </geometry>
            <material
                name="">
                <color
                rgba="0 0 1 1" />
            </material>
            </visual>
            <collision>
            <origin
                xyz="0 0 0"
                rpy="0 0 0" />
            <geometry>
                <mesh
                filename="package://quadruped_robot/meshes/qr_fl_link1.STL" />
            </geometry>
            </collision>
        </link>
        <joint
            name="qr_fl_link1_joint"
            type="revolute">
            <safety_controller k_position="100.0" k_velocity="40.0" soft_lower_limit="-3.14" soft_upper_limit="3.14"/>
            <origin
            xyz="0.012475 -0.05545 0"
            rpy="0 0 0" />
            <parent
            link="qr_link0" />
            <child
            link="qr_fl_link1" />
            <axis
            xyz="0 1 0" />
            <limit
            lower="${-pi/2}"
            upper="${pi/2}"
            effort="80"
            velocity="5" />
        </joint>
        <link
            name="qr_fl_link2">
            <inertial>
            <origin
                xyz="0.01555 0.014907 4.1099E-09"
                rpy="0 0 0" />
            <mass
                value="0.012214" />
            <inertia
                ixx="0"
                ixy="0"
                ixz="0"
                iyy="0"
                iyz="0"
                izz="0" />
            </inertial>
            <visual>
            <origin
                xyz="0 0 0"
                rpy="0 0 0" />
            <geometry>
                <mesh
                filename="package://quadruped_robot/meshes/qr_fl_link2.STL" />
            </geometry>
            <material
                name="">
                <color
                rgba="0 0 1 1" />
            </material>
            </visual>
            <collision>
            <origin
                xyz="0 0 0"
                rpy="0 0 0" />
            <geometry>
                <mesh
                filename="package://quadruped_robot/meshes/qr_fl_link2.STL" />
            </geometry>
            </collision>
        </link>
        <joint
            name="qr_fl_link2_joint"
            type="revolute">
            <safety_controller k_position="100.0" k_velocity="40.0" soft_lower_limit="-3.14" soft_upper_limit="3.14"/>
            <origin
            xyz="0.03645 -0.00615 0"
            rpy="0 0 0" />
            <parent
            link="qr_fl_link1" />
            <child
            link="qr_fl_link2" />
            <axis
            xyz="1 0 0" />
            <limit
            lower="${-pi/2}"
            upper="${pi/2}"
            effort="80"
            velocity="5" />
        </joint>
        <link
            name="qr_fl_link3">
            <inertial>
            <origin
                xyz="-0.000325 0.0002616 -0.013208"
                rpy="0 0 0" />
            <mass
                value="0.0010736" />
            <inertia
                ixx="0"
                ixy="0"
                ixz="0"
                iyy="0"
                iyz="0"
                izz="0" />
            </inertial>
            <visual>
            <origin
                xyz="0 0 0"
                rpy="0 0 0" />
            <geometry>
                <mesh
                filename="package://quadruped_robot/meshes/qr_fl_link3.STL" />
            </geometry>
            <material
                name="">
                <color
                rgba="0 0 1 1" />
            </material>
            </visual>
            <collision>
            <origin
                xyz="0 0 0"
                rpy="0 0 0" />
            <geometry>
                <mesh
                filename="package://quadruped_robot/meshes/qr_fl_link3.STL" />
            </geometry>
            </collision>
        </link>
        <joint
            name="qr_fl_link3_joint"
            type="revolute">
            <safety_controller k_position="100.0" k_velocity="40.0" soft_lower_limit="-3.14" soft_upper_limit="3.14"/>
            <origin
            xyz="0.002175 0.055 0"
            rpy="0 0 0" />
            <parent
            link="qr_fl_link2" />
            <child
            link="qr_fl_link3" />
            <axis
            xyz="1 0 0" />
            <limit
            lower="${-pi/2}"
            upper="${pi/2}"
            effort="80"
            velocity="5" />
        </joint>
        <link
            name="qr_fl_link4">
            <inertial>
            <origin
                xyz="0.00235 0 0"
                rpy="0 0 0" />
            <mass
                value="6.63661448070844E-05" />
            <inertia
                ixx="0"
                ixy="0"
                ixz="0"
                iyy="0"
                iyz="0"
                izz="0" />
            </inertial>
            <visual>
            <origin
                xyz="0 0 0"
                rpy="0 0 0" />
            <geometry>
                <mesh
                filename="package://quadruped_robot/meshes/qr_fl_link4.STL" />
            </geometry>
            <material
                name="">
                <color
                rgba="0 0 1 1" />
            </material>
            </visual>
            <collision>
            <origin
                xyz="0 0 0"
                rpy="0 0 0" />
            <geometry>
                <mesh
                filename="package://quadruped_robot/meshes/qr_fl_link4.STL" />
            </geometry>
            </collision>
        </link>
        <joint
            name="qr_fl_link4_joint"
            type="fixed">
            <origin
            xyz="-0.000325 0.0028868 -0.04"
            rpy="0 0 0" />
            <parent
            link="qr_fl_link3" />
            <child
            link="qr_fl_link4" />
            <axis
            xyz="0 0 0" />
        </joint>
        <link
            name="qr_fr_link1">
            <inertial>
            <origin
                xyz="-0.014583 6.439E-05 -0.00032117"
                rpy="0 0 0" />
            <mass
                value="0.011527" />
            <inertia
                ixx="0"
                ixy="0"
                ixz="0"
                iyy="0"
                iyz="0"
                izz="0" />
            </inertial>
            <visual>
            <origin
                xyz="0 0 0"
                rpy="0 0 0" />
            <geometry>
                <mesh
                filename="package://quadruped_robot/meshes/qr_fr_link1.STL" />
            </geometry>
            <material
                name="">
                <color
                rgba="0 0 1 1" />
            </material>
            </visual>
            <collision>
            <origin
                xyz="0 0 0"
                rpy="0 0 0" />
            <geometry>
                <mesh
                filename="package://quadruped_robot/meshes/qr_fr_link1.STL" />
            </geometry>
            </collision>
        </link>
        <joint
            name="qr_fr_link1_joint"
            type="revolute">
            <safety_controller k_position="100.0" k_velocity="40.0" soft_lower_limit="-3.14" soft_upper_limit="3.14"/>
            <origin
            xyz="-0.012475 -0.05545 0"
            rpy="0 0 0" />
            <parent
            link="qr_link0" />
            <child
            link="qr_fr_link1" />
            <axis
            xyz="0 1 0" />
            <limit
            lower="${-pi/2}"
            upper="${pi/2}"
            effort="80"
            velocity="5" />
        </joint>
        <link
            name="qr_fr_link2">
            <inertial>
            <origin
                xyz="-0.01555 0.014907 -4.1099E-09"
                rpy="0 0 0" />
            <mass
                value="0.012214" />
            <inertia
                ixx="0"
                ixy="0"
                ixz="0"
                iyy="0"
                iyz="0"
                izz="0" />
            </inertial>
            <visual>
            <origin
                xyz="0 0 0"
                rpy="0 0 0" />
            <geometry>
                <mesh
                filename="package://quadruped_robot/meshes/qr_fr_link2.STL" />
            </geometry>
            <material
                name="">
                <color
                rgba="0 0 1 1" />
            </material>
            </visual>
            <collision>
            <origin
                xyz="0 0 0"
                rpy="0 0 0" />
            <geometry>
                <mesh
                filename="package://quadruped_robot/meshes/qr_fr_link2.STL" />
            </geometry>
            </collision>
        </link>
        <joint
            name="qr_fr_link2_joint"
            type="revolute">
            <safety_controller k_position="100.0" k_velocity="40.0" soft_lower_limit="-3.14" soft_upper_limit="3.14"/>
            <origin
            xyz="-0.03645 -0.00615 0"
            rpy="0 0 0" />
            <parent
            link="qr_fr_link1" />
            <child
            link="qr_fr_link2" />
            <axis
            xyz="-1 0 0" />
            <limit
            lower="${-pi/2}"
            upper="${pi/2}"
            effort="80"
            velocity="5" />
        </joint>
        <link
            name="qr_fr_link3">
            <inertial>
            <origin
                xyz="0.000325 0.0002616 -0.013208"
                rpy="0 0 0" />
            <mass
                value="0.0010736" />
            <inertia
                ixx="0"
                ixy="0"
                ixz="0"
                iyy="0"
                iyz="0"
                izz="0" />
            </inertial>
            <visual>
            <origin
                xyz="0 0 0"
                rpy="0 0 0" />
            <geometry>
                <mesh
                filename="package://quadruped_robot/meshes/qr_fr_link3.STL" />
            </geometry>
            <material
                name="">
                <color
                rgba="0 0 1 1" />
            </material>
            </visual>
            <collision>
            <origin
                xyz="0 0 0"
                rpy="0 0 0" />
            <geometry>
                <mesh
                filename="package://quadruped_robot/meshes/qr_fr_link3.STL" />
            </geometry>
            </collision>
        </link>
        <joint
            name="qr_fr_link3_joint"
            type="revolute">
            <safety_controller k_position="100.0" k_velocity="40.0" soft_lower_limit="-3.14" soft_upper_limit="3.14"/>
            <origin
            xyz="-0.002175 0.055 0"
            rpy="0 0 0" />
            <parent
            link="qr_fr_link2" />
            <child
            link="qr_fr_link3" />
            <axis
            xyz="-1 0 0" />
            <limit
            lower="${-pi/2}"
            upper="${pi/2}"
            effort="80"
            velocity="5" />
        </joint>
        <link
            name="qr_fr_link4">
            <inertial>
            <origin
                xyz="-0.00235 0 0"
                rpy="0 0 0" />
            <mass
                value="6.63661448070845E-05" />
            <inertia
                ixx="0"
                ixy="0"
                ixz="0"
                iyy="0"
                iyz="0"
                izz="0" />
            </inertial>
            <visual>
            <origin
                xyz="0 0 0"
                rpy="0 0 0" />
            <geometry>
                <mesh
                filename="package://quadruped_robot/meshes/qr_fr_link4.STL" />
            </geometry>
            <material
                name="">
                <color
                rgba="0 0 1 1" />
            </material>
            </visual>
            <collision>
            <origin
                xyz="0 0 0"
                rpy="0 0 0" />
            <geometry>
                <mesh
                filename="package://quadruped_robot/meshes/qr_fr_link4.STL" />
            </geometry>
            </collision>
        </link>
        <joint
            name="qr_fr_link4_joint"
            type="fixed">
            <origin
            xyz="0.000325 0.0028868 -0.04"
            rpy="0 0 0" />
            <parent
            link="qr_fr_link3" />
            <child
            link="qr_fr_link4" />
            <axis
            xyz="0 0 0" />
        </joint>
        <link
            name="qr_bl_link1">
            <inertial>
            <origin
                xyz="0.014583 -6.439E-05 -0.00032117"
                rpy="0 0 0" />
            <mass
                value="0.011527" />
            <inertia
                ixx="0"
                ixy="0"
                ixz="0"
                iyy="0"
                iyz="0"
                izz="0" />
            </inertial>
            <visual>
            <origin
                xyz="0 0 0"
                rpy="0 0 0" />
            <geometry>
                <mesh
                filename="package://quadruped_robot/meshes/qr_bl_link1.STL" />
            </geometry>
            <material
                name="">
                <color
                rgba="0 0 1 1" />
            </material>
            </visual>
            <collision>
            <origin
                xyz="0 0 0"
                rpy="0 0 0" />
            <geometry>
                <mesh
                filename="package://quadruped_robot/meshes/qr_bl_link1.STL" />
            </geometry>
            </collision>
        </link>
        <joint
            name="qr_bl_link1_joint"
            type="revolute">
            <safety_controller k_position="100.0" k_velocity="40.0" soft_lower_limit="-3.14" soft_upper_limit="3.14"/>
            <origin
            xyz="0.012475 0.05545 0"
            rpy="0 0 0" />
            <parent
            link="qr_link0" />
            <child
            link="qr_bl_link1" />
            <axis
            xyz="0 -1 0" />
            <limit
            lower="${-pi/2}"
            upper="${pi/2}"
            effort="80"
            velocity="5" />
        </joint>
        <link
            name="qr_bl_link2">
            <inertial>
            <origin
                xyz="0.01555 0.014907 4.1099E-09"
                rpy="0 0 0" />
            <mass
                value="0.012214" />
            <inertia
                ixx="0"
                ixy="0"
                ixz="0"
                iyy="0"
                iyz="0"
                izz="0" />
            </inertial>
            <visual>
            <origin
                xyz="0 0 0"
                rpy="0 0 0" />
            <geometry>
                <mesh
                filename="package://quadruped_robot/meshes/qr_bl_link2.STL" />
            </geometry>
            <material
                name="">
                <color
                rgba="0 0 1 1" />
            </material>
            </visual>
            <collision>
            <origin
                xyz="0 0 0"
                rpy="0 0 0" />
            <geometry>
                <mesh
                filename="package://quadruped_robot/meshes/qr_bl_link2.STL" />
            </geometry>
            </collision>
        </link>
        <joint
            name="qr_bl_link2_joint"
            type="revolute">
            <safety_controller k_position="100.0" k_velocity="40.0" soft_lower_limit="-3.14" soft_upper_limit="3.14"/>
            <origin
            xyz="0.03645 0.00615 0"
            rpy="0 0 0" />
            <parent
            link="qr_bl_link1" />
            <child
            link="qr_bl_link2" />
            <axis
            xyz="1 0 0" />
            <limit
            lower="${-pi/2}"
            upper="${pi/2}"
            effort="80"
            velocity="5" />
        </joint>
        <link
            name="qr_bl_link3">
            <inertial>
            <origin
                xyz="-0.000325 0.0002616 -0.013208"
                rpy="0 0 0" />
            <mass
                value="0.0010736" />
            <inertia
                ixx="0"
                ixy="0"
                ixz="0"
                iyy="0"
                iyz="0"
                izz="0" />
            </inertial>
            <visual>
            <origin
                xyz="0 0 0"
                rpy="0 0 0" />
            <geometry>
                <mesh
                filename="package://quadruped_robot/meshes/qr_bl_link3.STL" />
            </geometry>
            <material
                name="">
                <color
                rgba="0 0 1 1" />
            </material>
            </visual>
            <collision>
            <origin
                xyz="0 0 0"
                rpy="0 0 0" />
            <geometry>
                <mesh
                filename="package://quadruped_robot/meshes/qr_bl_link3.STL" />
            </geometry>
            </collision>
        </link>
        <joint
            name="qr_bl_link3_joint"
            type="revolute">
            <safety_controller k_position="100.0" k_velocity="40.0" soft_lower_limit="-3.14" soft_upper_limit="3.14"/>
            <origin
            xyz="0.002175 0.055 0"
            rpy="0 0 0" />
            <parent
            link="qr_bl_link2" />
            <child
            link="qr_bl_link3" />
            <axis
            xyz="1 0 0" />
            <limit
            lower="${-pi/2}"
            upper="${pi/2}"
            effort="80"
            velocity="5" />
        </joint>
        <link
            name="qr_bl_link4">
            <inertial>
            <origin
                xyz="0.00235 0 0"
                rpy="0 0 0" />
            <mass
                value="6.6366E-05" />
            <inertia
                ixx="0"
                ixy="0"
                ixz="0"
                iyy="0"
                iyz="0"
                izz="0" />
            </inertial>
            <visual>
            <origin
                xyz="0 0 0"
                rpy="0 0 0" />
            <geometry>
                <mesh
                filename="package://quadruped_robot/meshes/qr_bl_link4.STL" />
            </geometry>
            <material
                name="">
                <color
                rgba="0 0 1 1" />
            </material>
            </visual>
            <collision>
            <origin
                xyz="0 0 0"
                rpy="0 0 0" />
            <geometry>
                <mesh
                filename="package://quadruped_robot/meshes/qr_bl_link4.STL" />
            </geometry>
            </collision>
        </link>
        <joint
            name="qr_bl_link4_joint"
            type="fixed">
            <origin
            xyz="-0.000325 0.0028868 -0.04"
            rpy="0 0 0" />
            <parent
            link="qr_bl_link3" />
            <child
            link="qr_bl_link4" />
            <axis
            xyz="0 0 0" />
        </joint>
        <link
            name="qr_br_link1">
            <inertial>
            <origin
                xyz="-0.014583 -6.439E-05 -0.00032117"
                rpy="0 0 0" />
            <mass
                value="0.011527" />
            <inertia
                ixx="0"
                ixy="0"
                ixz="0"
                iyy="0"
                iyz="0"
                izz="0" />
            </inertial>
            <visual>
            <origin
                xyz="0 0 0"
                rpy="0 0 0" />
            <geometry>
                <mesh
                filename="package://quadruped_robot/meshes/qr_br_link1.STL" />
            </geometry>
            <material
                name="">
                <color
                rgba="0 0 1 1" />
            </material>
            </visual>
            <collision>
            <origin
                xyz="0 0 0"
                rpy="0 0 0" />
            <geometry>
                <mesh
                filename="package://quadruped_robot/meshes/qr_br_link1.STL" />
            </geometry>
            </collision>
        </link>
        <joint
            name="qr_br_link1_joint"
            type="revolute">
            <safety_controller k_position="100.0" k_velocity="40.0" soft_lower_limit="-3.14" soft_upper_limit="3.14"/>
            <origin
            xyz="-0.012475 0.05545 0"
            rpy="0 0 0" />
            <parent
            link="qr_link0" />
            <child
            link="qr_br_link1" />
            <axis
            xyz="0 -1 0" />
            <limit
            lower="${-pi/2}"
            upper="${pi/2}"
            effort="80"
            velocity="5" />
        </joint>
        <link
            name="qr_br_link2">
            <inertial>
            <origin
                xyz="-0.01555 0.014907 -4.1099E-09"
                rpy="0 0 0" />
            <mass
                value="0.012214" />
            <inertia
                ixx="0"
                ixy="0"
                ixz="0"
                iyy="0"
                iyz="0"
                izz="0" />
            </inertial>
            <visual>
            <origin
                xyz="0 0 0"
                rpy="0 0 0" />
            <geometry>
                <mesh
                filename="package://quadruped_robot/meshes/qr_br_link2.STL" />
            </geometry>
            <material
                name="">
                <color
                rgba="0 0 1 1" />
            </material>
            </visual>
            <collision>
            <origin
                xyz="0 0 0"
                rpy="0 0 0" />
            <geometry>
                <mesh
                filename="package://quadruped_robot/meshes/qr_br_link2.STL" />
            </geometry>
            </collision>
        </link>
        <joint
            name="qr_br_link2_joint"
            type="revolute">
            <safety_controller k_position="100.0" k_velocity="40.0" soft_lower_limit="-3.14" soft_upper_limit="3.14"/>
            <origin
            xyz="-0.03645 0.00615 0"
            rpy="0 0 0" />
            <parent
            link="qr_br_link1" />
            <child
            link="qr_br_link2" />
            <axis
            xyz="-1 0 0" />
            <limit
            lower="${-pi/2}"
            upper="${pi/2}"
            effort="80"
            velocity="5" />
        </joint>
        <link
            name="qr_br_link3">
            <inertial>
            <origin
                xyz="0.000325 0.0002616 -0.013208"
                rpy="0 0 0" />
            <mass
                value="0.0010736" />
            <inertia
                ixx="0"
                ixy="0"
                ixz="0"
                iyy="0"
                iyz="0"
                izz="0" />
            </inertial>
            <visual>
            <origin
                xyz="0 0 0"
                rpy="0 0 0" />
            <geometry>
                <mesh
                filename="package://quadruped_robot/meshes/qr_br_link3.STL" />
            </geometry>
            <material
                name="">
                <color
                rgba="0 0 1 1" />
            </material>
            </visual>
            <collision>
            <origin
                xyz="0 0 0"
                rpy="0 0 0" />
            <geometry>
                <mesh
                filename="package://quadruped_robot/meshes/qr_br_link3.STL" />
            </geometry>
            </collision>
        </link>
        <joint
            name="qr_br_link3_joint"
            type="revolute">
            <safety_controller k_position="100.0" k_velocity="40.0" soft_lower_limit="-3.14" soft_upper_limit="3.14"/>
            <origin
            xyz="-0.002175 0.055 0"
            rpy="0 0 0" />
            <parent
            link="qr_br_link2" />
            <child
            link="qr_br_link3" />
            <axis
            xyz="-1 0 0" />
            <limit
            lower="${-pi/2}"
            upper="${pi/2}"
            effort="80"
            velocity="5" />
        </joint>
        <link
            name="qr_br_link4">
            <inertial>
            <origin
                xyz="-0.00235 0 0"
                rpy="0 0 0" />
            <mass
                value="6.6366E-05" />
            <inertia
                ixx="0"
                ixy="0"
                ixz="0"
                iyy="0"
                iyz="0"
                izz="0" />
            </inertial>
            <visual>
            <origin
                xyz="0 0 0"
                rpy="0 0 0" />
            <geometry>
                <mesh
                filename="package://quadruped_robot/meshes/qr_br_link4.STL" />
            </geometry>
            <material
                name="">
                <color
                rgba="0 0 1 1" />
            </material>
            </visual>
            <collision>
            <origin
                xyz="0 0 0"
                rpy="0 0 0" />
            <geometry>
                <mesh
                filename="package://quadruped_robot/meshes/qr_br_link4.STL" />
            </geometry>
            </collision>
        </link>
        <joint
            name="qr_br_link4_joint"
            type="fixed">
            <origin
            xyz="0.000325 0.0028868 -0.04"
            rpy="0 0 0" />
            <parent
            link="qr_br_link3" />
            <child
            link="qr_br_link4" />
            <axis
            xyz="0 0 0" />
        </joint>
    </xacro:macro>
</robot>