<?xml version="1.0" ?>
<!-- =================================================================================== -->
<!-- |    This document was autogenerated by xacro from /home/victor-m/ws_moveit/src/rover_assembly/urdf/rover_assembly.urdf.xacro | -->
<!-- |    EDITING THIS FILE BY HAND IS NOT RECOMMENDED                                 | -->
<!-- =================================================================================== -->
<robot name="rover_assembly">
    <!-- Is the robot being simulated in gazebo? -->
    <link name="rover_body">
        
<inertial>
            <origin rpy="0 0 0" xyz="0.0024064 -0.10248 -0.051695" />
            <mass value="50.286" />
            <inertia ixx="12.892" ixy="0.079855" ixz="-0.10325" iyy="15.217" iyz="3.3541" izz="18.99" />
        </inertial>

        <visual>
            <origin rpy="0 0 0" xyz="0 0 0" />
            <geometry>
                <mesh filename="package://rover_assembly/meshes/rover_body.STL" />
            </geometry>
            <material name="">
                <color rgba="0.79216 0.81961 0.93333 1" />
            </material>
        </visual>
        <collision>
            <origin rpy="0 0 0" xyz="0 0 0" />
            <geometry>
                <mesh filename="package://rover_assembly/meshes/rover_body.STL" />
            </geometry>
        </collision>
    </link>
    <link name="wheel1">
        
<inertial>
            <origin rpy="0 0 0" xyz="-0.59774 0.25947 0.19243" />
            <mass value="50.286" />
            <inertia ixx="12.892" ixy="0.079855" ixz="-0.10325" iyy="15.217" iyz="3.3541" izz="18.99" />
        </inertial>

        <visual>
            <origin rpy="0 0 0" xyz="0 0 0" />
            <geometry>
                <mesh filename="package://rover_assembly/meshes/wheel1.STL" />
            </geometry>
            <material name="">
                <color rgba="0.79216 0.81961 0.93333 1" />
            </material>
        </visual>
        <collision>
            <origin rpy="0 0 0" xyz="0 0 0" />
            <geometry>
                <mesh filename="package://rover_assembly/meshes/wheel1.STL" />
            </geometry>
        </collision>
    </link>
    <joint name="wheel1_joint" type="continuous">
        <origin rpy="0 0 0" xyz="0.60014 -0.36195 -0.24413" />
        <parent link="rover_body" />
        <child link="wheel1" />
        <axis xyz="1 0 0" />
        <limit effort="80" lower="0" upper="0" velocity="25" />
    </joint>
    <link name="wheel2">
        
<inertial>
            <origin rpy="0 0 0" xyz="-0.59774 -0.46443 0.19243" />
            <mass value="50.286" />
            <inertia ixx="12.892" ixy="0.079855" ixz="-0.10325" iyy="15.217" iyz="3.3541" izz="18.99" />
        </inertial>

        <visual>
            <origin rpy="0 0 0" xyz="0 0 0" />
            <geometry>
                <mesh filename="package://rover_assembly/meshes/wheel2.STL" />
            </geometry>
            <material name="">
                <color rgba="0.79216 0.81961 0.93333 1" />
            </material>
        </visual>
        <collision>
            <origin rpy="0 0 0" xyz="0 0 0" />
            <geometry>
                <mesh filename="package://rover_assembly/meshes/wheel2.STL" />
            </geometry>
        </collision>
    </link>
    <joint name="wheel2_joint" type="continuous">
        <origin rpy="0 0 0" xyz="0.60014 0.36195 -0.24413" />
        <parent link="rover_body" />
        <child link="wheel2" />
        <axis xyz="1 0 0" />
        <limit effort="80" lower="0" upper="0" velocity="25" />
    </joint>
    <link name="wheel3">
        
<inertial>
            <origin rpy="0 0 0" xyz="0.60255 0.25947 0.19243" />
            <mass value="50.286" />
            <inertia ixx="12.892" ixy="0.079855" ixz="-0.10325" iyy="15.217" iyz="3.3541" izz="18.99" />
        </inertial>

        <visual>
            <origin rpy="0 0 0" xyz="0 0 0" />
            <geometry>
                <mesh filename="package://rover_assembly/meshes/wheel3.STL" />
            </geometry>
            <material name="">
                <color rgba="0.79216 0.81961 0.93333 1" />
            </material>
        </visual>
        <collision>
            <origin rpy="0 0 0" xyz="0 0 0" />
            <geometry>
                <mesh filename="package://rover_assembly/meshes/wheel3.STL" />
            </geometry>
        </collision>
    </link>
    <joint name="wheel3_joint" type="continuous">
        <origin rpy="0 0 0" xyz="-0.60014 -0.36195 -0.24413" />
        <parent link="rover_body" />
        <child link="wheel3" />
        <axis xyz="-1 0 0" />
        <limit effort="80" lower="0" upper="0" velocity="25" />
    </joint>
    <link name="wheel4">
        
<inertial>
            <origin rpy="0 0 0" xyz="0.60255 -0.46443 0.19243" />
            <mass value="50.286" />
            <inertia ixx="12.892" ixy="0.079855" ixz="-0.10325" iyy="15.217" iyz="3.3541" izz="18.99" />
        </inertial>

        <visual>
            <origin rpy="0 0 0" xyz="0 0 0" />
            <geometry>
                <mesh filename="package://rover_assembly/meshes/wheel4.STL" />
            </geometry>
            <material name="">
                <color rgba="0.79216 0.81961 0.93333 1" />
            </material>
        </visual>
        <collision>
            <origin rpy="0 0 0" xyz="0 0 0" />
            <geometry>
                <mesh filename="package://rover_assembly/meshes/wheel4.STL" />
            </geometry>
        </collision>
    </link>
    <joint name="wheel4_joint" type="continuous">
        <origin rpy="0 0 0" xyz="-0.60014 0.36195 -0.24413" />
        <parent link="rover_body" />
        <child link="wheel4" />
        <axis xyz="-1 0 0" />
        <limit effort="80" lower="0" upper="0" velocity="25" />
    </joint>
    <link name="arm_link0">
        
<inertial>
            <origin rpy="0 0 0" xyz="0.0024064 0.20232 0.037205" />
            <mass value="50.286" />
            <inertia ixx="12.892" ixy="0.079855" ixz="-0.10325" iyy="15.217" iyz="3.3541" izz="18.99" />
        </inertial>

        <visual>
            <origin rpy="0 0 0" xyz="0 0 0" />
            <geometry>
                <mesh filename="package://rover_assembly/meshes/arm_link0.STL" />
            </geometry>
            <material name="">
                <color rgba="0.79216 0.81961 0.93333 1" />
            </material>
        </visual>
        <collision>
            <origin rpy="0 0 0" xyz="0 0 0" />
            <geometry>
                <mesh filename="package://rover_assembly/meshes/arm_link0.STL" />
            </geometry>
        </collision>
    </link>
    <joint name="arm_link0_joint" type="fixed">
        <origin rpy="0 0 0" xyz="0 -0.3048 -0.0889" />
        <parent link="rover_body" />
        <child link="arm_link0" />
        <axis xyz="0 0 0" />
    </joint>
    <link name="arm_link1">
        
<inertial>
            <origin rpy="0 0 0" xyz="0.002508 0.20222 -0.18634" />
            <mass value="50.286" />
            <inertia ixx="12.892" ixy="0.079855" ixz="-0.10325" iyy="15.217" iyz="3.3541" izz="18.99" />
        </inertial>

        <visual>
            <origin rpy="0 0 0" xyz="0 0 0" />
            <geometry>
                <mesh filename="package://rover_assembly/meshes/arm_link1.STL" />
            </geometry>
            <material name="">
                <color rgba="0.79216 0.81961 0.93333 1" />
            </material>
        </visual>
        <collision>
            <origin rpy="0 0 0" xyz="0 0 0" />
            <geometry>
                <mesh filename="package://rover_assembly/meshes/arm_link1.STL" />
            </geometry>
        </collision>
    </link>
    <joint name="arm_link1_joint" type="revolute">
        <origin rpy="0 0 0" xyz="-0.0001016 0.0001016 0.22355" />
        <parent link="arm_link0" />
        <child link="arm_link1" />
        <axis xyz="0 0 -1" />
        <limit effort="80" lower="-3.14" upper="3.14" velocity="25" />
    </joint>
    <link name="arm_link2">
        
<inertial>
            <origin rpy="0 0 0" xyz="0.0025039 0.25327 -0.23154" />
            <mass value="50.286" />
            <inertia ixx="12.892" ixy="0.079855" ixz="-0.10325" iyy="15.217" iyz="3.3541" izz="18.99" />
        </inertial>

        <visual>
            <origin rpy="0 0 0" xyz="0 0 0" />
            <geometry>
                <mesh filename="package://rover_assembly/meshes/arm_link2.STL" />
            </geometry>
            <material name="">
                <color rgba="0.79216 0.81961 0.93333 1" />
            </material>
        </visual>
        <collision>
            <origin rpy="0 0 0" xyz="0 0 0" />
            <geometry>
                <mesh filename="package://rover_assembly/meshes/arm_link2.STL" />
            </geometry>
        </collision>
    </link>
    <joint name="arm_link2_joint" type="revolute">
        <origin rpy="0 0 0" xyz="0 -0.051052 0.0452" />
        <parent link="arm_link1" />
        <child link="arm_link2" />
        <axis xyz="-1 0 0" />
        <limit effort="80" lower="-3.14" upper="3.14" velocity="25" />
    </joint>
    <link name="arm_link3">
        
<inertial>
            <origin rpy="0 0 0" xyz="0.0025039 0.25327 -0.84114" />
            <mass value="50.286" />
            <inertia ixx="12.892" ixy="0.079855" ixz="-0.10325" iyy="15.217" iyz="3.3541" izz="18.99" />
        </inertial>

        <visual>
            <origin rpy="0 0 0" xyz="0 0 0" />
            <geometry>
                <mesh filename="package://rover_assembly/meshes/arm_link3.STL" />
            </geometry>
            <material name="">
                <color rgba="0.79216 0.81961 0.93333 1" />
            </material>
        </visual>
        <collision>
            <origin rpy="0 0 0" xyz="0 0 0" />
            <geometry>
                <mesh filename="package://rover_assembly/meshes/arm_link3.STL" />
            </geometry>
        </collision>
    </link>
    <joint name="arm_link3_joint" type="revolute">
        <origin rpy="0 0 0" xyz="0 0 0.6096" />
        <parent link="arm_link2" />
        <child link="arm_link3" />
        <axis xyz="1 0 0" />
        <limit effort="80" lower="-3.14" upper="3.14" velocity="25" />
    </joint>
    <link name="arm_link4">
        
<inertial>
            <origin rpy="0 0 0" xyz="-0.078271 0.73551 -0.83511" />
            <mass value="50.286" />
            <inertia ixx="12.892" ixy="0.079855" ixz="-0.10325" iyy="15.217" iyz="3.3541" izz="18.99" />
        </inertial>

        <visual>
            <origin rpy="0 0 0" xyz="0 0 0" />
            <geometry>
                <mesh filename="package://rover_assembly/meshes/arm_link4.STL" />
            </geometry>
            <material name="">
                <color rgba="0.79216 0.81961 0.93333 1" />
            </material>
        </visual>
        <collision>
            <origin rpy="0 0 0" xyz="0 0 0" />
            <geometry>
                <mesh filename="package://rover_assembly/meshes/arm_link4.STL" />
            </geometry>
        </collision>
    </link>
    <joint name="arm_link4_joint" type="revolute">
        <origin rpy="0 0 0" xyz="0.080775 -0.48223 -0.0060298" />
        <parent link="arm_link3" />
        <child link="arm_link4" />
        <axis xyz="1 0 0" />
        <limit effort="80" lower="-3.14" upper="3.14" velocity="25" />
    </joint>
    <link name="arm_link5">
        
<inertial>
            <origin rpy="0 0 0" xyz="0.0027494 0.75779 -0.86837" />
            <mass value="50.286" />
            <inertia ixx="12.892" ixy="0.079855" ixz="-0.10325" iyy="15.217" iyz="3.3541" izz="18.99" />
        </inertial>

        <visual>
            <origin rpy="0 0 0" xyz="0 0 0" />
            <geometry>
                <mesh filename="package://rover_assembly/meshes/arm_link5.STL" />
            </geometry>
            <material name="">
                <color rgba="0.79216 0.81961 0.93333 1" />
            </material>
        </visual>
        <collision>
            <origin rpy="0 0 0" xyz="0 0 0" />
            <geometry>
                <mesh filename="package://rover_assembly/meshes/arm_link5.STL" />
            </geometry>
        </collision>
    </link>
    <joint name="arm_link5_joint" type="revolute">
        <origin rpy="0 0 0" xyz="-0.08102 -0.02228 0.03326" />
        <parent link="arm_link4" />
        <child link="arm_link5" />
        <axis xyz="0 -1 0" />
        <limit effort="80" lower="-3.14" upper="3.14" velocity="25" />
    </joint>
    <link name="gripper_finger1">
        
<inertial>
            <origin rpy="0 0 0" xyz="-0.011165 -0.085231 -0.000127" />
            <mass value="0.020758" />
            <inertia ixx="5.6257E-05" ixy="-1.6742E-05" ixz="-2.6977E-19" iyy="1.1909E-05" iyz="-3.7402E-19" izz="6.7392E-05" />
        </inertial>

        <visual>
            <origin rpy="0 0 0" xyz="0 0 0" />
            <geometry>
                <mesh filename="package://rover_assembly/meshes/gripper_finger1.STL" />
            </geometry>
            <material name="">
                <color rgba="1 1 1 1" />
            </material>
        </visual>
        <collision>
            <origin rpy="0 0 0" xyz="0 0 0" />
            <geometry>
                <mesh filename="package://rover_assembly/meshes/gripper_finger1.STL" />
            </geometry>
        </collision>
    </link>
    <joint name="gripper_finger1_joint" type="revolute">
        <origin rpy="0 0 0" xyz="0.0762 -0.13859 0" />
        <parent link="arm_link5" />
        <child link="gripper_finger1" />
        <axis xyz="0 0 1" />
        <limit effort="80" lower="-3.14" upper="0" velocity="25" />
    </joint>
    <link name="gripper_finger2">
        
<inertial>
            <origin rpy="0 0 0" xyz="-0.011165 -0.085231 -0.000127" />
            <mass value="0.020758" />
            <inertia ixx="5.6257E-05" ixy="-1.6742E-05" ixz="-3.151E-19" iyy="1.1909E-05" iyz="-4.8787E-19" izz="6.7392E-05" />
        </inertial>

        <visual>
            <origin rpy="0 0 0" xyz="0 0 0" />
            <geometry>
                <mesh filename="package://rover_assembly/meshes/gripper_finger2.STL" />
            </geometry>
            <material name="">
                <color rgba="1 1 1 1" />
            </material>
        </visual>
        <collision>
            <origin rpy="0 0 0" xyz="0 0 0" />
            <geometry>
                <mesh filename="package://rover_assembly/meshes/gripper_finger2.STL" />
            </geometry>
        </collision>
    </link>
    <joint name="gripper_finger2_joint" type="revolute">
        <origin rpy="-3.1416 -1.0472 -3.1416" xyz="-0.0381 -0.13859 0.065991" />
        <parent link="arm_link5" />
        <child link="gripper_finger2" />
        <axis xyz="0 0 1" />
        <limit effort="80" lower="-3.14" upper="0" velocity="25" />
    </joint>
    <link name="gripper_finger3">
        
<inertial>
            <origin rpy="0 0 0" xyz="-0.011165 -0.085231 -0.000127" />
            <mass value="0.020758" />
            <inertia ixx="5.6257E-05" ixy="-1.6742E-05" ixz="-3.3034E-19" iyy="1.1909E-05" iyz="-4.7659E-19" izz="6.7392E-05" />
        </inertial>

        <visual>
            <origin rpy="0 0 0" xyz="0 0 0" />
            <geometry>
                <mesh filename="package://rover_assembly/meshes/gripper_finger3.STL" />
            </geometry>
            <material name="">
                <color rgba="1 1 1 1" />
            </material>
        </visual>
        <collision>
            <origin rpy="0 0 0" xyz="0 0 0" />
            <geometry>
                <mesh filename="package://rover_assembly/meshes/gripper_finger3.STL" />
            </geometry>
        </collision>
    </link>
    <joint name="gripper_finger3_joint" type="revolute">
        <origin rpy="-3.1416 1.0472 -3.1416" xyz="-0.0381 -0.13859 -0.065991" />
        <parent link="arm_link5" />
        <child link="gripper_finger3" />
        <axis xyz="0 0 1" />
        <limit effort="80" lower="-3.14" upper="0" velocity="25" />
    </joint>
    
<transmission name="trans_wheel1_joint">
        <type>transmission_interface/SimpleTransmission</type>
        <joint name="wheel1_joint">
            <hardwareInterface>hardware_interface/VelocityJointInterface</hardwareInterface>
        </joint>
        <actuator name="wheel1_joint_motor">
            <hardwareInterface>hardware_interface/VelocityJointInterface</hardwareInterface>
            <mechanicalReduction>1</mechanicalReduction>
        </actuator>
    </transmission>
    <transmission name="trans_wheel2_joint">
        <type>transmission_interface/SimpleTransmission</type>
        <joint name="wheel2_joint">
            <hardwareInterface>hardware_interface/VelocityJointInterface</hardwareInterface>
        </joint>
        <actuator name="wheel2_joint_motor">
            <hardwareInterface>hardware_interface/VelocityJointInterface</hardwareInterface>
            <mechanicalReduction>1</mechanicalReduction>
        </actuator>
    </transmission>
    <transmission name="trans_wheel3_joint">
        <type>transmission_interface/SimpleTransmission</type>
        <joint name="wheel3_joint">
            <hardwareInterface>hardware_interface/VelocityJointInterface</hardwareInterface>
        </joint>
        <actuator name="wheel3_joint_motor">
            <hardwareInterface>hardware_interface/VelocityJointInterface</hardwareInterface>
            <mechanicalReduction>1</mechanicalReduction>
        </actuator>
    </transmission>
    <transmission name="trans_wheel4_joint">
        <type>transmission_interface/SimpleTransmission</type>
        <joint name="wheel4_joint">
            <hardwareInterface>hardware_interface/VelocityJointInterface</hardwareInterface>
        </joint>
        <actuator name="wheel4_joint_motor">
            <hardwareInterface>hardware_interface/VelocityJointInterface</hardwareInterface>
            <mechanicalReduction>1</mechanicalReduction>
        </actuator>
    </transmission>
    <transmission name="trans_arm_link1_joint">
        <type>transmission_interface/SimpleTransmission</type>
        <joint name="arm_link1_joint">
            <hardwareInterface>hardware_interface/PositionJointInterface</hardwareInterface>
        </joint>
        <actuator name="arm_link1_joint_motor">
            <hardwareInterface>hardware_interface/PositionJointInterface</hardwareInterface>
            <mechanicalReduction>1</mechanicalReduction>
        </actuator>
    </transmission>
    <transmission name="trans_arm_link2_joint">
        <type>transmission_interface/SimpleTransmission</type>
        <joint name="arm_link2_joint">
            <hardwareInterface>hardware_interface/PositionJointInterface</hardwareInterface>
        </joint>
        <actuator name="arm_link2_joint_motor">
            <hardwareInterface>hardware_interface/PositionJointInterface</hardwareInterface>
            <mechanicalReduction>1</mechanicalReduction>
        </actuator>
    </transmission>
    <transmission name="trans_arm_link3_joint">
        <type>transmission_interface/SimpleTransmission</type>
        <joint name="arm_link3_joint">
            <hardwareInterface>hardware_interface/PositionJointInterface</hardwareInterface>
        </joint>
        <actuator name="arm_link3_joint_motor">
            <hardwareInterface>hardware_interface/PositionJointInterface</hardwareInterface>
            <mechanicalReduction>1</mechanicalReduction>
        </actuator>
    </transmission>
    <transmission name="trans_arm_link4_joint">
        <type>transmission_interface/SimpleTransmission</type>
        <joint name="arm_link4_joint">
            <hardwareInterface>hardware_interface/PositionJointInterface</hardwareInterface>
        </joint>
        <actuator name="arm_link4_joint_motor">
            <hardwareInterface>hardware_interface/PositionJointInterface</hardwareInterface>
            <mechanicalReduction>1</mechanicalReduction>
        </actuator>
    </transmission>
    <transmission name="trans_arm_link5_joint">
        <type>transmission_interface/SimpleTransmission</type>
        <joint name="arm_link5_joint">
            <hardwareInterface>hardware_interface/PositionJointInterface</hardwareInterface>
        </joint>
        <actuator name="arm_link5_joint_motor">
            <hardwareInterface>hardware_interface/PositionJointInterface</hardwareInterface>
            <mechanicalReduction>1</mechanicalReduction>
        </actuator>
    </transmission>
    <transmission name="trans_gripper_finger1_joint">
        <type>transmission_interface/SimpleTransmission</type>
        <joint name="gripper_finger1_joint">
            <hardwareInterface>hardware_interface/EffortJointInterface</hardwareInterface>
        </joint>
        <actuator name="gripper_finger1_joint_motor">
            <hardwareInterface>hardware_interface/EffortJointInterface</hardwareInterface>
            <mechanicalReduction>1</mechanicalReduction>
        </actuator>
    </transmission>
    <transmission name="trans_gripper_finger2_joint">
        <type>transmission_interface/SimpleTransmission</type>
        <joint name="gripper_finger2_joint">
            <hardwareInterface>hardware_interface/EffortJointInterface</hardwareInterface>
        </joint>
        <actuator name="gripper_finger2_joint_motor">
            <hardwareInterface>hardware_interface/EffortJointInterface</hardwareInterface>
            <mechanicalReduction>1</mechanicalReduction>
        </actuator>
    </transmission>
    <transmission name="trans_gripper_finger3_joint">
        <type>transmission_interface/SimpleTransmission</type>
        <joint name="gripper_finger3_joint">
            <hardwareInterface>hardware_interface/EffortJointInterface</hardwareInterface>
        </joint>
        <actuator name="gripper_finger3_joint_motor">
            <hardwareInterface>hardware_interface/EffortJointInterface</hardwareInterface>
            <mechanicalReduction>1</mechanicalReduction>
        </actuator>
    </transmission>
    <gazebo>
        <plugin name="gazebo_ros_control" filename="libgazebo_ros_control.so">
            <robotNamespace>/</robotNamespace>
        </plugin>
    </gazebo>
</robot>