<?xml version="1.0" encoding="utf-8"?>
<robot xmlns:xacro="http://www.ros.org/wiki/xacro" name="rover_assembly">
    <xacro:macro name="rover_assembly" params="rover_id:='rover_assembly' description_pkg:='' connected_to:='' xyz:='0 0 0' rpy:='0 0 0' safety_distance:=0">
        <xacro:unless value="${not connected_to}">
            <joint name="${connected_to}_joint" type="fixed">
                <parent link="${connected_to}"/>
                <child link="rover_body"/>
                <origin rpy="{rpy}" xyz="${xyz}"/>
            </joint>
        </xacro:unless>

        <link
            name="rover_body">
            <inertial>
            <origin
                xyz="0.0024064 -0.10248 -0.051695"
                rpy="0 0 0" />
            <mass
                value="50.286" />
            <inertia
                ixx="12.892"
                ixy="0.079855"
                ixz="-0.10325"
                iyy="15.217"
                iyz="3.3541"
                izz="18.99" />
            </inertial>
            <visual>
            <origin
                xyz="0 0 0"
                rpy="0 0 0" />
            <geometry>
                <mesh
                filename="package://rover_assembly/meshes/rover_body.STL" />
            </geometry>
            <material
                name="">
                <color
                rgba="0.79216 0.81961 0.93333 1" />
            </material>
            </visual>
            <collision>
            <origin
                xyz="0 0 0"
                rpy="0 0 0" />
            <geometry>
                <mesh
                filename="package://rover_assembly/meshes/rover_body.STL" />
            </geometry>
            </collision>
        </link>
        <link
            name="wheel1">
            <inertial>
            <origin
                xyz="-0.59774 0.25947 0.19243"
                rpy="0 0 0" />
            <mass
                value="50.286" />
            <inertia
                ixx="12.892"
                ixy="0.079855"
                ixz="-0.10325"
                iyy="15.217"
                iyz="3.3541"
                izz="18.99" />
            </inertial>
            <visual>
            <origin
                xyz="0 0 0"
                rpy="0 0 0" />
            <geometry>
                <mesh
                filename="package://rover_assembly/meshes/wheel1.STL" />
            </geometry>
            <material
                name="">
                <color
                rgba="0.79216 0.81961 0.93333 1" />
            </material>
            </visual>
            <collision>
            <origin
                xyz="0 0 0"
                rpy="0 0 0" />
            <geometry>
                <mesh
                filename="package://rover_assembly/meshes/wheel1.STL" />
            </geometry>
            </collision>
        </link>
        <joint
            name="wheel1_joint"
            type="continuous">
            <origin
            xyz="0.60014 -0.36195 -0.24413"
            rpy="0 0 0" />
            <parent
            link="rover_body" />
            <child
            link="wheel1" />
            <axis
            xyz="1 0 0" />
            <limit
            lower="0"
            upper="0"
            effort="80"
            velocity="25" />
        </joint>
        <link
            name="wheel2">
            <inertial>
            <origin
                xyz="-0.59774 -0.46443 0.19243"
                rpy="0 0 0" />
            <mass
                value="50.286" />
            <inertia
                ixx="12.892"
                ixy="0.079855"
                ixz="-0.10325"
                iyy="15.217"
                iyz="3.3541"
                izz="18.99" />
            </inertial>
            <visual>
            <origin
                xyz="0 0 0"
                rpy="0 0 0" />
            <geometry>
                <mesh
                filename="package://rover_assembly/meshes/wheel2.STL" />
            </geometry>
            <material
                name="">
                <color
                rgba="0.79216 0.81961 0.93333 1" />
            </material>
            </visual>
            <collision>
            <origin
                xyz="0 0 0"
                rpy="0 0 0" />
            <geometry>
                <mesh
                filename="package://rover_assembly/meshes/wheel2.STL" />
            </geometry>
            </collision>
        </link>
        <joint
            name="wheel2_joint"
            type="continuous">
            <origin
            xyz="0.60014 0.36195 -0.24413"
            rpy="0 0 0" />
            <parent
            link="rover_body" />
            <child
            link="wheel2" />
            <axis
            xyz="1 0 0" />
            <limit
            lower="0"
            upper="0"
            effort="80"
            velocity="25" />
        </joint>
        <link
            name="wheel3">
            <inertial>
            <origin
                xyz="0.60255 0.25947 0.19243"
                rpy="0 0 0" />
            <mass
                value="50.286" />
            <inertia
                ixx="12.892"
                ixy="0.079855"
                ixz="-0.10325"
                iyy="15.217"
                iyz="3.3541"
                izz="18.99" />
            </inertial>
            <visual>
            <origin
                xyz="0 0 0"
                rpy="0 0 0" />
            <geometry>
                <mesh
                filename="package://rover_assembly/meshes/wheel3.STL" />
            </geometry>
            <material
                name="">
                <color
                rgba="0.79216 0.81961 0.93333 1" />
            </material>
            </visual>
            <collision>
            <origin
                xyz="0 0 0"
                rpy="0 0 0" />
            <geometry>
                <mesh
                filename="package://rover_assembly/meshes/wheel3.STL" />
            </geometry>
            </collision>
        </link>
        <joint
            name="wheel3_joint"
            type="continuous">
            <origin
            xyz="-0.60014 -0.36195 -0.24413"
            rpy="0 0 0" />
            <parent
            link="rover_body" />
            <child
            link="wheel3" />
            <axis
            xyz="-1 0 0" />
            <limit
            lower="0"
            upper="0"
            effort="80"
            velocity="25" />
        </joint>
        <link
            name="wheel4">
            <inertial>
            <origin
                xyz="0.60255 -0.46443 0.19243"
                rpy="0 0 0" />
            <mass
                value="50.286" />
            <inertia
                ixx="12.892"
                ixy="0.079855"
                ixz="-0.10325"
                iyy="15.217"
                iyz="3.3541"
                izz="18.99" />
            </inertial>
            <visual>
            <origin
                xyz="0 0 0"
                rpy="0 0 0" />
            <geometry>
                <mesh
                filename="package://rover_assembly/meshes/wheel4.STL" />
            </geometry>
            <material
                name="">
                <color
                rgba="0.79216 0.81961 0.93333 1" />
            </material>
            </visual>
            <collision>
            <origin
                xyz="0 0 0"
                rpy="0 0 0" />
            <geometry>
                <mesh
                filename="package://rover_assembly/meshes/wheel4.STL" />
            </geometry>
            </collision>
        </link>
        <joint
            name="wheel4_joint"
            type="continuous">
            <origin
            xyz="-0.60014 0.36195 -0.24413"
            rpy="0 0 0" />
            <parent
            link="rover_body" />
            <child
            link="wheel4" />
            <axis
            xyz="-1 0 0" />
            <limit
            lower="0"
            upper="0"
            effort="80"
            velocity="25" />
        </joint>
        <link
            name="arm_link0">
            <inertial>
            <origin
                xyz="0.0024064 0.20232 0.037205"
                rpy="0 0 0" />
            <mass
                value="50.286" />
            <inertia
                ixx="12.892"
                ixy="0.079855"
                ixz="-0.10325"
                iyy="15.217"
                iyz="3.3541"
                izz="18.99" />
            </inertial>
            <visual>
            <origin
                xyz="0 0 0"
                rpy="0 0 0" />
            <geometry>
                <mesh
                filename="package://rover_assembly/meshes/arm_link0.STL" />
            </geometry>
            <material
                name="">
                <color
                rgba="0.79216 0.81961 0.93333 1" />
            </material>
            </visual>
            <collision>
            <origin
                xyz="0 0 0"
                rpy="0 0 0" />
            <geometry>
                <mesh
                filename="package://rover_assembly/meshes/arm_link0.STL" />
            </geometry>
            </collision>
        </link>
        <joint
            name="arm_link0_joint"
            type="fixed">
            <origin
            xyz="0 -0.3048 -0.0889"
            rpy="0 0 0" />
            <parent
            link="rover_body" />
            <child
            link="arm_link0" />
            <axis
            xyz="0 0 0" />
        </joint>
        <link
            name="arm_link1">
            <inertial>
            <origin
                xyz="0.002508 0.20222 -0.18634"
                rpy="0 0 0" />
            <mass
                value="50.286" />
            <inertia
                ixx="12.892"
                ixy="0.079855"
                ixz="-0.10325"
                iyy="15.217"
                iyz="3.3541"
                izz="18.99" />
            </inertial>
            <visual>
            <origin
                xyz="0 0 0"
                rpy="0 0 0" />
            <geometry>
                <mesh
                filename="package://rover_assembly/meshes/arm_link1.STL" />
            </geometry>
            <material
                name="">
                <color
                rgba="0.79216 0.81961 0.93333 1" />
            </material>
            </visual>
            <collision>
            <origin
                xyz="0 0 0"
                rpy="0 0 0" />
            <geometry>
                <mesh
                filename="package://rover_assembly/meshes/arm_link1.STL" />
            </geometry>
            </collision>
        </link>
        <joint
            name="arm_link1_joint"
            type="revolute">
            <origin
            xyz="-0.0001016 0.0001016 0.22355"
            rpy="0 0 0" />
            <parent
            link="arm_link0" />
            <child
            link="arm_link1" />
            <axis
            xyz="0 0 -1" />
            <limit
            lower="-3.14"
            upper="3.14"
            effort="80"
            velocity="25" />
        </joint>
        <link
            name="arm_link2">
            <inertial>
            <origin
                xyz="0.0025039 0.25327 -0.23154"
                rpy="0 0 0" />
            <mass
                value="50.286" />
            <inertia
                ixx="12.892"
                ixy="0.079855"
                ixz="-0.10325"
                iyy="15.217"
                iyz="3.3541"
                izz="18.99" />
            </inertial>
            <visual>
            <origin
                xyz="0 0 0"
                rpy="0 0 0" />
            <geometry>
                <mesh
                filename="package://rover_assembly/meshes/arm_link2.STL" />
            </geometry>
            <material
                name="">
                <color
                rgba="0.79216 0.81961 0.93333 1" />
            </material>
            </visual>
            <collision>
            <origin
                xyz="0 0 0"
                rpy="0 0 0" />
            <geometry>
                <mesh
                filename="package://rover_assembly/meshes/arm_link2.STL" />
            </geometry>
            </collision>
        </link>
        <joint
            name="arm_link2_joint"
            type="revolute">
            <origin
            xyz="0 -0.051052 0.0452"
            rpy="0 0 0" />
            <parent
            link="arm_link1" />
            <child
            link="arm_link2" />
            <axis
            xyz="-1 0 0" />
            <limit
            lower="-3.14"
            upper="3.14"
            effort="80"
            velocity="25" />
        </joint>
        <link
            name="arm_link3">
            <inertial>
            <origin
                xyz="0.0025039 0.25327 -0.84114"
                rpy="0 0 0" />
            <mass
                value="50.286" />
            <inertia
                ixx="12.892"
                ixy="0.079855"
                ixz="-0.10325"
                iyy="15.217"
                iyz="3.3541"
                izz="18.99" />
            </inertial>
            <visual>
            <origin
                xyz="0 0 0"
                rpy="0 0 0" />
            <geometry>
                <mesh
                filename="package://rover_assembly/meshes/arm_link3.STL" />
            </geometry>
            <material
                name="">
                <color
                rgba="0.79216 0.81961 0.93333 1" />
            </material>
            </visual>
            <collision>
            <origin
                xyz="0 0 0"
                rpy="0 0 0" />
            <geometry>
                <mesh
                filename="package://rover_assembly/meshes/arm_link3.STL" />
            </geometry>
            </collision>
        </link>
        <joint
            name="arm_link3_joint"
            type="revolute">
            <origin
            xyz="0 0 0.6096"
            rpy="0 0 0" />
            <parent
            link="arm_link2" />
            <child
            link="arm_link3" />
            <axis
            xyz="1 0 0" />
            <limit
            lower="-3.14"
            upper="3.14"
            effort="80"
            velocity="25" />
        </joint>
        <link
            name="arm_link4">
            <inertial>
            <origin
                xyz="-0.078271 0.73551 -0.83511"
                rpy="0 0 0" />
            <mass
                value="50.286" />
            <inertia
                ixx="12.892"
                ixy="0.079855"
                ixz="-0.10325"
                iyy="15.217"
                iyz="3.3541"
                izz="18.99" />
            </inertial>
            <visual>
            <origin
                xyz="0 0 0"
                rpy="0 0 0" />
            <geometry>
                <mesh
                filename="package://rover_assembly/meshes/arm_link4.STL" />
            </geometry>
            <material
                name="">
                <color
                rgba="0.79216 0.81961 0.93333 1" />
            </material>
            </visual>
            <collision>
            <origin
                xyz="0 0 0"
                rpy="0 0 0" />
            <geometry>
                <mesh
                filename="package://rover_assembly/meshes/arm_link4.STL" />
            </geometry>
            </collision>
        </link>
        <joint
            name="arm_link4_joint"
            type="revolute">
            <origin
            xyz="0.080775 -0.48223 -0.0060298"
            rpy="0 0 0" />
            <parent
            link="arm_link3" />
            <child
            link="arm_link4" />
            <axis
            xyz="1 0 0" />
            <limit
            lower="-3.14"
            upper="3.14"
            effort="80"
            velocity="25" />
        </joint>
        <link
            name="arm_link5">
            <inertial>
            <origin
                xyz="0.0027494 0.75779 -0.86837"
                rpy="0 0 0" />
            <mass
                value="50.286" />
            <inertia
                ixx="12.892"
                ixy="0.079855"
                ixz="-0.10325"
                iyy="15.217"
                iyz="3.3541"
                izz="18.99" />
            </inertial>
            <visual>
            <origin
                xyz="0 0 0"
                rpy="0 0 0" />
            <geometry>
                <mesh
                filename="package://rover_assembly/meshes/arm_link5.STL" />
            </geometry>
            <material
                name="">
                <color
                rgba="0.79216 0.81961 0.93333 1" />
            </material>
            </visual>
            <collision>
            <origin
                xyz="0 0 0"
                rpy="0 0 0" />
            <geometry>
                <mesh
                filename="package://rover_assembly/meshes/arm_link5.STL" />
            </geometry>
            </collision>
        </link>
        <joint
            name="arm_link5_joint"
            type="revolute">
            <origin
            xyz="-0.08102 -0.02228 0.03326"
            rpy="0 0 0" />
            <parent
            link="arm_link4" />
            <child
            link="arm_link5" />
            <axis
            xyz="0 -1 0" />
            <limit
            lower="-3.14"
            upper="3.14"
            effort="80"
            velocity="25" />
        </joint>
        <link
            name="gripper_finger1">
            <inertial>
            <origin
                xyz="-0.011165 -0.085231 -0.000127"
                rpy="0 0 0" />
            <mass
                value="0.020758" />
            <inertia
                ixx="5.6257E-05"
                ixy="-1.6742E-05"
                ixz="-2.6977E-19"
                iyy="1.1909E-05"
                iyz="-3.7402E-19"
                izz="6.7392E-05" />
            </inertial>
            <visual>
            <origin
                xyz="0 0 0"
                rpy="0 0 0" />
            <geometry>
                <mesh
                filename="package://rover_assembly/meshes/gripper_finger1.STL" />
            </geometry>
            <material
                name="">
                <color
                rgba="1 1 1 1" />
            </material>
            </visual>
            <collision>
            <origin
                xyz="0 0 0"
                rpy="0 0 0" />
            <geometry>
                <mesh
                filename="package://rover_assembly/meshes/gripper_finger1.STL" />
            </geometry>
            </collision>
        </link>
        <joint
            name="gripper_finger1_joint"
            type="revolute">
            <origin
            xyz="0.0762 -0.13859 0"
            rpy="0 0 0" />
            <parent
            link="arm_link5" />
            <child
            link="gripper_finger1" />
            <axis
            xyz="0 0 1" />
            <limit
            lower="-3.14"
            upper="0"
            effort="80"
            velocity="25" />
        </joint>
        <link
            name="gripper_finger2">
            <inertial>
            <origin
                xyz="-0.011165 -0.085231 -0.000127"
                rpy="0 0 0" />
            <mass
                value="0.020758" />
            <inertia
                ixx="5.6257E-05"
                ixy="-1.6742E-05"
                ixz="-3.151E-19"
                iyy="1.1909E-05"
                iyz="-4.8787E-19"
                izz="6.7392E-05" />
            </inertial>
            <visual>
            <origin
                xyz="0 0 0"
                rpy="0 0 0" />
            <geometry>
                <mesh
                filename="package://rover_assembly/meshes/gripper_finger2.STL" />
            </geometry>
            <material
                name="">
                <color
                rgba="1 1 1 1" />
            </material>
            </visual>
            <collision>
            <origin
                xyz="0 0 0"
                rpy="0 0 0" />
            <geometry>
                <mesh
                filename="package://rover_assembly/meshes/gripper_finger2.STL" />
            </geometry>
            </collision>
        </link>
        <joint
            name="gripper_finger2_joint"
            type="revolute">
            <origin
            xyz="-0.0381 -0.13859 0.065991"
            rpy="-3.1416 -1.0472 -3.1416" />
            <parent
            link="arm_link5" />
            <child
            link="gripper_finger2" />
            <axis
            xyz="0 0 1" />
            <limit
            lower="-3.14"
            upper="0"
            effort="80"
            velocity="25" />
        </joint>
        <link
            name="gripper_finger3">
            <inertial>
            <origin
                xyz="-0.011165 -0.085231 -0.000127"
                rpy="0 0 0" />
            <mass
                value="0.020758" />
            <inertia
                ixx="5.6257E-05"
                ixy="-1.6742E-05"
                ixz="-3.3034E-19"
                iyy="1.1909E-05"
                iyz="-4.7659E-19"
                izz="6.7392E-05" />
            </inertial>
            <visual>
            <origin
                xyz="0 0 0"
                rpy="0 0 0" />
            <geometry>
                <mesh
                filename="package://rover_assembly/meshes/gripper_finger3.STL" />
            </geometry>
            <material
                name="">
                <color
                rgba="1 1 1 1" />
            </material>
            </visual>
            <collision>
            <origin
                xyz="0 0 0"
                rpy="0 0 0" />
            <geometry>
                <mesh
                filename="package://rover_assembly/meshes/gripper_finger3.STL" />
            </geometry>
            </collision>
        </link>
        <joint
            name="gripper_finger3_joint"
            type="revolute">
            <origin
            xyz="-0.0381 -0.13859 -0.065991"
            rpy="-3.1416 1.0472 -3.1416" />
            <parent
            link="arm_link5" />
            <child
            link="gripper_finger3" />
            <axis
            xyz="0 0 1" />
            <limit
            lower="-3.14"
            upper="0"
            effort="80"
            velocity="25" />
        </joint>
        
    </xacro:macro>
</robot>